Workbook

Sheet 요약
A1: 3기 종료 리포트 QA — 요약 (dev 10/7 빌드 · 2026-10-12)
A2: QA 기준 = 피그마(목업 + 디스크립션, 페이지 1028:3313). TC 시트의 결과 칸을 채우면 아래 숫자가 자동으로 바뀝니다. 배포 판단: P1에 실패가 하나라도 있으면 배포 불가.
A4: 우선순위 | B4: 의미 | C4: 전체 | D4: 통과 | E4: 실패 | F4: 보류 | G4: 미실행/빈칸 | H4: 통과율
A5: P1 | B5: 배포 차단 | C5: =COUNTIF(TC!$B$2:$B$52,A5) | D5: =COUNTIFS(TC!$B$2:$B$52,A5,TC!$N$2:$N$52,"통과") | E5: =COUNTIFS(TC!$B$2:$B$52,A5,TC!$N$2:$N$52,"실패") | F5: =COUNTIFS(TC!$B$2:$B$52,A5,TC!$N$2:$N$52,"보류") | G5: =C5-D5-E5-F5-COUNTIFS(TC!$B$2:$B$52,A5,TC!$N$2:$N$52,"해당없음") | H5: =IF(C5=0,0,D5/C5)
A6: P2 | B6: 화면 · 문구 | C6: =COUNTIF(TC!$B$2:$B$52,A6) | D6: =COUNTIFS(TC!$B$2:$B$52,A6,TC!$N$2:$N$52,"통과") | E6: =COUNTIFS(TC!$B$2:$B$52,A6,TC!$N$2:$N$52,"실패") | F6: =COUNTIFS(TC!$B$2:$B$52,A6,TC!$N$2:$N$52,"보류") | G6: =C6-D6-E6-F6-COUNTIFS(TC!$B$2:$B$52,A6,TC!$N$2:$N$52,"해당없음") | H6: =IF(C6=0,0,D6/C6)
A7: P3 | B7: 예외 · 환경 | C7: =COUNTIF(TC!$B$2:$B$52,A7) | D7: =COUNTIFS(TC!$B$2:$B$52,A7,TC!$N$2:$N$52,"통과") | E7: =COUNTIFS(TC!$B$2:$B$52,A7,TC!$N$2:$N$52,"실패") | F7: =COUNTIFS(TC!$B$2:$B$52,A7,TC!$N$2:$N$52,"보류") | G7: =C7-D7-E7-F7-COUNTIFS(TC!$B$2:$B$52,A7,TC!$N$2:$N$52,"해당없음") | H7: =IF(C7=0,0,D7/C7)
A8: 합계 | C8: =SUM(C5:C7) | D8: =SUM(D5:D7) | E8: =SUM(E5:E7) | F8: =SUM(F5:F7) | G8: =SUM(G5:G7) | H8: =IF(C8=0,0,D8/C8)
A10: 배포 판단 | B10: =IF(E5>0,"배포 불가 — P1 실패 "&E5&"건",IF(G5+F5>0,"판단 보류 — P1 미완료 "&(G5+F5)&"건","배포 가능"))
A11: ※ 결과는 앱 결과(N열, Android 기준) 기준으로 셉니다. iOS는 O열에 따로 적어 주세요.
A13: 결함 | D13: 피그마 정리
A14: 전체 | B14: 열림 | C14: 해결 | D14: 건수
A15: =COUNTIF(결함!$A$2:$A$60,"BUG-*") | B15: =A15-C15 | C15: =COUNTIF(결함!$E$2:$E$60,"해결") | D15: =COUNTIF('피그마 정리'!$A$2:$A$40,"FIG-*")
A17: 결정 필요
A18: 전체 | B18: 결정됨 | C18: 남음
A19: =COUNTIF('결정 필요'!$A$2:$A$9,"Q-*") | B19: =COUNTIF('결정 필요'!$F$2:$F$9,"?*") | C19: =A19-B19
A21: 칸 색 안내
B22: 노란 칸 = 직접 입력 (결과 · 실제 결과 · 결함 ID · 증빙 · 테스터 · 날짜 · 결정)
B23: 초록 칸 = 기획이 웹 샘플로 먼저 본 결과 (10/12). 앱에서 다시 확인해 N · O열에 적어 주세요

Sheet TC
A1: TC ID | B1: 우선순위 | C1: 여정 단계 | D1: 화면 | E1: 테스트 계정 | F1: 환경 | G1: 사전 조건 | H1: 테스트 절차 | I1: 기대 결과 | J1: 근거(정본) | K1: 참고 스크린샷 | L1: 웹 샘플 결과(기획) | M1: 웹 샘플 메모 | N1: 결과 Android | O1: 결과 iOS | P1: 실제 결과 | Q1: 결함 ID | R1: 증빙 스크린샷 링크 | S1: 테스터 | T1: 테스트일
A2: E-01 | B2: P1 | C2: 1 진입 | D2: 체험 홈 | E2: ① | F2: 앱 | G2: dev 빌드 설치 · 로그인 | H2: 체험 홈으로 들어간다 | I2: 상단에 3기 리포트 카드(전용 배너 이미지)가 보인다 | J2: B-01 · IA-R-08 | N2: 미실행
A3: E-02 | B3: P1 | C3: 1 진입 | D3: 자동 팝업 | E3: ① | F3: 앱 | G3: 리포트를 한 번도 열지 않은 상태 | H3: 로그인 직후 홈 진입 | I3: 리포트가 자동으로 1회 열리고 표지(SC-RP-01)부터 보인다 | J3: IA-R-01 | K3: cmp_01.png | N3: 미실행
A4: E-03 | B4: P2 | C4: 1 진입 | D4: 자동 팝업 | E4: ① | F4: 앱 | G4: E-02 이후 | H4: 리포트를 닫고 앱을 껐다 다시 연다 | I4: 자동 팝업이 다시 뜨지 않는다 · 홈 카드는 그대로 있다 | J4: IA-R-01 | N4: 미실행
A5: E-04 | B5: P1 | C5: 1 진입 | D5: 홈 카드 | E5: ① | F5: 앱 | G5: — | H5: 홈 카드를 누른다 | I5: 리포트가 표지부터 열린다 | J5: IA-R-03 | N5: 미실행
A6: E-05 | B6: P1 | C6: 1 진입 | D6: 진행 내역 | E6: ① | F6: 앱 | G6: 10/20 제출 빌드 | H6: 내 정보 > 프로그램 진행 내역 > 3기 항목을 누른다 | I6: 리포트가 표지부터 열린다 | J6: F4 · IA-R-07 | N6: 미실행
A7: E-06 | B7: P2 | C7: 1 진입 | D7: 체험 홈 | E7: ⑤ | F7: 앱 | G7: 다른 프로그램 진행 중 | H7: 홈으로 들어간다 | I7: 리포트 카드가 없다 | J7: IA-R-08 | N7: 미실행
A8: E-07 | B8: P2 | C8: 1 진입 | D8: 공개 전 | E8: ⑥ | F8: 앱 | G8: — | H8: 홈 확인 후 리포트 링크로 직접 연다 | I8: 카드 없음 · "아직 볼 수 없어요" 안내 | J8: P09 | N8: 미실행
A9: E-08 | B9: P1 | C9: 1 진입 | D9: 비대상 P20 | E9: ⑦ | F9: 앱 · 웹 | G9: — | H9: 리포트 링크로 직접 연다 | I9: 제목 없이 본문 "2026년 인천 남동구 보건소 두뇌운동 치매 예방 교실 3기 참여자에게만 제공되는 리포트입니다. 자세한 문의는 인천 남동구 보건소로 문의 부탁드립니다." + [홈으로 돌아가기] | J9: P20 · gate-nontarget | K9: cmp_sys05.png | L9: 실패 | M9: 문구는 일치 · 아이콘 · 버튼 배치 다름 → BUG-07 | N9: 미실행
A10: E-09 | B10: P1 | C10: 1 진입 | D10: 강제 업데이트 | E10: 아무 계정 | F10: 앱 | G10: 앱 4.1.0 이하 설치 | H10: 앱을 연다 | I10: 4.1.1 미만은 업데이트 안내 · 앱 사용 차단 | J10: K-15 · IA-R-13 · 개발 D-5 | N10: 미실행
A11: E-10 | B11: P1 | C11: 1 진입 | D11: 네트워크 오류 | E11: ① | F11: 앱 | G11: 비행기 모드 | H11: 홈 카드를 누른다 | I11: 전체 화면 오류 + [다시 시도] · "참여자에게만" 문구가 나오지 않는다 | J11: P18 | N11: 미실행
A12: S-01 | B12: P2 | C12: 2 8개 섹션 | D12: 01 표지 | E12: ② ③ ④ | F12: 앱 · 웹 | G12: — | H12: 표지를 본다 | I12: 피그마 목업처럼 배지 "2026 인천 남동구 보건소 치매 예방 3기" · "{마스킹 이름}님," · 기간 · 참여일 · 왼쪽 정렬 · 메달 그래픽 | J12: S1-01~04 · 목업 1097:791 | K12: cmp_01.png | L12: 실패 | M12: 문구 일치 · 가운데 정렬 · 메달 없음 → BUG-03 | N12: 미실행
A13: S-02 | B13: P1 | C13: 2 8개 섹션 | D13: 02 숫자로 먼저 | E13: ② | F13: 앱 | G13: §데이터 요청 5번 원값 수령 | H13: 화면 숫자와 원값을 대조한다 | I13: 뇌 점수 시작→종료 · 함께한 날 · 참여율 · 게임 횟수 · 마음 기록이 원값과 같다 | J13: S2 · F-01~F-04 · F-08 | K13: cmp_02.png | L13: 실패 | M13: 숫자 정상 · 꺾은선이 거의 평평 → BUG-04 | N13: 미실행
A14: S-03 | B14: P2 | C14: 2 8개 섹션 | D14: 03 집중의 리듬 | E14: ② | F14: 앱 · 웹 | G14: — | H14: 요일 · 시간 · 막대를 본다 | I14: 월~금만 · "프로그램 운영일은 평일(월–금)입니다" | J14: S3 · F-07 | K14: cmp_03.png | L14: 실패 | M14: 88% 강조색 · 멘트 카드 다름 → BUG-05 | N14: 미실행
A15: S-04 | B15: P2 | C15: 2 8개 섹션 | D15: 04 게임 | E15: ② | F15: 앱 · 웹 | G15: — | H15: 최다 게임 · 횟수 · 종수 · TOP3 | I15: "해본 게임 N종 / 전체 16종 중" · TOP3 정렬 | J15: S4 · F-03b · F-05 | K15: cmp_04.png | L15: 통과 | M15: 게임명 줄바꿈만 다름 → BUG-09 (P3) | N15: 미실행
A16: S-05 | B16: P1 | C16: 2 8개 섹션 | D16: 04B 랭킹 | E16: ② ① | F16: 앱 · 웹 | G16: — | H16: 순위 · 상위 % 타일 · 배지 · 하단 문구 | I16: 타일 % = 배지 % · 1~3위면 내 행 없음 · "아래로 {823-순위}명이 더 함께했어요" · 최하위면 문구 없음 | J16: S4B-04~08 · F-06 · F-06b · P08 | K16: cmp_04B.png | L16: 통과 | M16: 12위 · 상위 2% · 811명 · 목업과 같음 | N16: 미실행
A17: S-06 | B17: P2 | C17: 2 8개 섹션 | D17: 05 마음 | E17: ② + 측정 1회 · 0회 계정 | F17: 앱 · 웹 | G17: 측정 1회 · 0회 계정은 개발에 요청 | H17: 게이지 · 상태 · 안내박스 | I17: 종료 점수 구간으로 판정 · 1회면 고스트 없음 · 0회면 "검사 기록이 없습니다." | J17: S5 · P03 · P04 | K17: cmp_05.png | L17: 통과 | M17: 7→3점 양호 · 라벨 위치만 다름 → BUG-09 (P3) | N17: 미실행
A18: S-07 | B18: P2 | C18: 2 8개 섹션 | D18: 06 걸음 | E18: ② + 미연동 계정 | F18: 앱 · 웹 | G18: 미연동 계정은 개발에 요청 | H18: 걸음 · 환산 · 칼로리 | I18: 미연동이면 섹션 자체 없음 · 7km 미만이면 환산 카드 없음 · N=1이면 회차 없이 "걸었어요" | J18: S6 · P16 · P17 | K18: cmp_06.png | L18: 통과 | M18: 목업과 같음 | N18: 미실행
A19: S-08 | B19: P2 | C19: 2 8개 섹션 | D19: 스크롤 힌트 | E19: ② | F19: 앱 | G19: 작은 폰(iPhone SE급) | H19: 각 섹션에 들어간 직후와 스크롤한 뒤 | I19: 진입 직후만 하단 고정 · 스크롤하면 풀림 · 본문을 계속 가리지 않음 | J19: S1-05 · FE-05 | K19: cmp_05.png | L19: 보류 | M19: 375×812 웹에서 진입 직후 힌트가 05 안내박스를 가림 → BUG-08 · 앱에서 확인 | N19: 미실행
A20: S-09 | B20: P1 | C20: 2 8개 섹션 | D20: 닫기 버튼 | E20: ① | F20: 앱 | G20: — | H20: 아무 섹션에서 스크롤 중 | I20: ✕가 항상 우상단에 고정 | J20: S1-06 | N20: 미실행
A21: S-10 | B21: P3 | C21: 2 8개 섹션 | D21: 큰 글씨 | E21: ② | F21: 앱 | G21: OS 글자 크기 최대 | H21: 전 섹션을 본다 | I21: 줄 넘침 · 겹침 · 잘림 없음 | J21: IA-R-14 · D-28 | N21: 미실행
A22: C-01 | B22: P1 | C22: 3 증서 저장 | D22: 07 A | E22: ① | F22: 앱 | G22: 사진 권한 허용 | H22: 수료증 저장하기 | I22: 사진첩에 1:1 이미지 1장 · 숫자 0이나 빈칸 없음 | J22: S7-10 · §12 | K22: cmp_07A.png | M22: 웹은 앱 브리지가 없어 저장 버튼 비활성(정상) · 테두리 장식 없음 → BUG-06 | N22: 미실행
A23: C-02 | B23: P1 | C23: 3 증서 저장 | D23: 07 A | E23: ① | F23: 앱 | G23: C-01 이후 | H23: 파일명 · 형식 확인 | I23: 맬리브레인_3기_수료증_{원문이름} · Android JPEG / iOS PNG | J23: S7-10 · Q-10 | N23: 미실행
A24: C-03 | B24: P2 | C24: 3 증서 저장 | D24: 07 B | E24: ③ | F24: 앱 · 웹 | G24: — | H24: 참여기록 저장하기 | I24: 라벨 "참여기록 저장하기" · 파일명 …_참여기록_… | J24: S7-10 · Q-02 | K24: cmp_07B.png | L24: 통과 | M24: 라벨 확인(웹) | N24: 미실행
A25: C-04 | B25: P1 | C25: 3 증서 저장 | D25: 07 C | E25: ④ | F25: 앱 · 웹 | G25: — | H25: 증서 화면 | I25: 저장 버튼 없음 · 참여 실적 줄 없음 · 4기 · 홈 버튼만 | J25: S7-08 · S7-10 | K25: cmp_07C.png | L25: 통과 | N25: 미실행
A26: C-05 | B26: P3 | C26: 3 증서 저장 | D26: 07 A | E26: ① | F26: 앱 | G26: 사진 권한 거부 | H26: 수료증 저장하기 | I26: 권한 안내 · 앱이 멈추지 않음 | J26: P15 | N26: 미실행
A27: C-06 | B27: P2 | C27: 3 증서 저장 | D27: 07 A | E27: ① | F27: 앱 | G27: — | H27: 저장 후 | I27: 리포트가 닫히지 않고 그대로 | J27: IA-R-10 | N27: 미실행
A28: C-07 | B28: P2 | C28: 3 증서 저장 | D28: 07 A | E28: ① | F28: 앱 · 웹 | G28: — | H28: 증서 이름 확인 | I28: 표지는 마스킹(김*리) · 증서는 원문 이름 | J28: S7-06 · P12 | K28: cmp_07A.png | L28: 통과 | N28: 미실행
A29: A-01 | B29: P1 | C29: 4 4기 신청 | D29: 07-h 시트 | E29: ① | F29: 앱 · 웹 | G29: — | H29: 4기도 참여하기 | I29: 바텀시트 · 문구는 결정 Q-1대로 · [닫기] [네, 신청합니다] | J29: 07-h · K-13 | K29: cmp_07h.png | L29: 통과 | M29: 목업과 같음 · 명칭에 4기 없음은 결정 Q-1 | N29: 미실행
A30: A-02 | B30: P2 | C30: 4 4기 신청 | D30: 07-h 시트 | E30: ① | F30: 앱 · 웹 | G30: — | H30: [닫기] / 딤 탭 | I30: 시트만 닫힘 · 신청 저장 안 됨 | J30: 07-h | L30: 통과 | M30: [닫기] 확인(웹) | N30: 미실행
A31: A-03 | B31: P1 | C31: 4 4기 신청 | D31: 08 완료 | E31: ① | F31: 앱 · 웹 | G31: — | H31: [네, 신청합니다] | I31: 완료 화면 · 본문 4줄 "4기가 시작될 때 보건소에서 연락드리겠습니다. 자세한 문의사항은 032-453-6160으로 문의 바랍니다. 감사합니다." | J31: SC-RP-08 · S8-05 · K-14 | K31: cmp_08.png | L31: 실패 | M31: 배치는 목업과 같음 · 첫 줄 누락 · 번호 6163 → BUG-01 · 02 | N31: 미실행
A32: A-04 | B32: P2 | C32: 4 4기 신청 | D32: 08 완료 | E32: ① | F32: 앱 | G32: — | H32: [네, 신청합니다] 연타 | I32: 신청 1건만 저장 | J32: IA-R-12 | N32: 미실행
A33: A-05 | B33: P1 | C33: 4 4기 신청 | D33: 07-l | E33: ① | F33: 앱 · 웹 | G33: A-03 이후 | H33: 홈 → 리포트 다시 열기 | I33: 4기 버튼 비활성 + "4기 신청이 완료되었습니다" | J33: 07-l · IA-R-12 | K33: cmp_07l.png | L33: 통과 | M33: state=07l · 목업과 같음 | N33: 미실행
A34: A-06 | B34: P1 | C34: 4 4기 신청 | D34: 07-l | E34: ① | F34: 앱 | G34: A-03 이후 | H34: 다른 폰에서 같은 계정 로그인 | I34: 07-l 상태 그대로 (서버 값 기준) | J34: apply.season4_applied | N34: 미실행
A35: A-07 | B35: P1 | C35: 4 4기 신청 | D35: 08-a 실패 | E35: ① | F35: 앱 | G35: 비행기 모드 | H35: [네, 신청합니다] | I35: 실패 화면 · 제목은 FIG-03 결정대로 · 032-453-6160 · [다시 시도] 누르면 확인 없이 자동 재신청 | J35: 08-a · S8-06 | L35: 미실행 | M35: 웹 샘플 없음 → 개발에 state=08a 요청 | N35: 미실행
A36: A-08 | B36: P2 | C36: 4 4기 신청 | D36: 07-l | E36: ② | F36: 앱 | G36: — | H36: 리포트 열기 | I36: 처음부터 07-l | J36: 07-l | N36: 미실행
A37: A-09 | B37: P1 | C37: 4 4기 신청 | D37: 07-m | E37: ⑤ | F37: 앱 | G37: — | H37: 증서 화면 | I37: 4기 버튼 없음 | J37: 07-m | N37: 미실행
A38: A-10 | B38: P2 | C38: 4 4기 신청 | D38: 노출 시점 | E38: 운영 | F38: 앱 | G38: 10/27 출시 빌드 | H38: 출시 전 · 후 버튼 노출 | I38: 10/27부터 노출 | J38: S7-11 | N38: 미실행
A39: X-01 | B39: P1 | C39: 5 닫기 · 뒤로가기 | D39: 공통 | E39: ① | F39: 앱 | G39: — | H39: 아무 섹션에서 ✕ | I39: 홈으로 복귀 | J39: IA-R-05 | N39: 미실행
A40: X-02 | B40: P1 | C40: 5 닫기 · 뒤로가기 | D40: 공통 | E40: ① | F40: Android | G40: — | H40: 리포트 / 시트 열림 / 완료 화면에서 뒤로가기 | I40: 시트가 열려 있으면 시트만 닫힘 · 그 외 홈 | J40: IA-R-05 | N40: 미실행
...

Sheet 결함
A1: 결함 ID | B1: 제목 | C1: 심각도 | D1: 우선순위 | E1: 상태 | F1: 화면 | G1: 재현 경로 | H1: 기대 결과(피그마) | I1: 실제 결과(dev) | J1: 스크린샷 | K1: 근거 | L1: 담당 | M1: 관련 TC | N1: 메모 · 회신
A2: BUG-01 | B2: 문의 전화번호 6163 → 대표번호 6160 | C2: Major | D2: P1 | E2: 개발 수정 | F2: SC-RP-08 완료 · 실패 · 신청폼 · 문자 | G2: https://dev-meli-web.meli.health/report-3gi?state=nice → 4기도 참여하기 → 네, 신청합니다 | H2: 032-453-6160 (보건소 대표번호 · 10/12 확정 · 피그마 S8-05 디스크립션) | I2: 032-453-6163 | J2: cmp_08.png | K2: K-14 · 변경이력 39 | L2: 개발 | M2: PH-01 · A-03 · A-07
A3: BUG-02 | B3: 4기 신청 완료 본문 첫 줄 누락 | C3: Major | D3: P1 | E3: 기획 선행 | F3: SC-RP-08 완료 | G3: https://dev-meli-web.meli.health/report-3gi/apply?state=nice | H3: 4줄: 4기가 시작될 때 보건소에서 / 연락드리겠습니다. / 자세한 문의사항은 032-453-6160으로 / 문의 바랍니다. 감사합니다. (피그마 S8-05 디스크립션) | I3: 2줄: 자세한 문의사항은 … 문의 바랍니다. 감사합니다. — 피그마 목업 카드(1463:1286)가 아직 2줄이라 개발이 목업을 따름 | J3: cmp_08.png | K3: S8-05 · FIG-01 | L3: 기획(피그마 목업 수정) → 개발 | M3: A-03
A4: BUG-03 | B4: 표지 정렬 · 히어로 그래픽이 목업과 다름 | C4: Minor | D4: P2 | E4: 확인 필요 | F4: SC-RP-01 표지 | G4: https://dev-meli-web.meli.health/report-3gi?state=nice 첫 화면 | H4: 배지 · 이름 · 기간 왼쪽 정렬 / 캐릭터 뒤 메달(리본 + 원형 배경) | I4: 가운데 정렬 / 메달 없이 캐릭터만 | J4: cmp_01.png | K4: SC-RP-01 목업 1097:791 · Q-11 | L4: 개발 (메달은 10/13 3D 에셋 확인 후) | M4: S-01
A5: BUG-04 | B5: 뇌 점수 꺾은선이 거의 평평함 | C5: Minor | D5: P2 | E5: 개발 수정 | F5: SC-RP-02 | G5: https://dev-meli-web.meli.health/report-3gi?state=nice 두 번째 화면 | H5: 69점 → 77점이 눈에 띄게 올라가는 선 · 10월 라벨 강조 (목업) | I5: 시작과 끝이 거의 수평 · 10월 라벨 강조 없음 | J5: cmp_02.png | K5: S2-05 | L5: 개발 | M5: S-02
A6: BUG-05 | B6: 요일 퍼센트 강조색 · 개인화 멘트 카드가 목업과 다름 | C6: Minor | D6: P2 | E6: 확인 필요 | F6: SC-RP-03 | G6: https://dev-meli-web.meli.health/report-3gi?state=nice 세 번째 화면 | H6: 최다 요일 퍼센트(88%) 녹색 / 멘트 카드는 원형 캐릭터 없이 헤드라인 1줄 (목업) | I6: 88% 검정 / 왼쪽에 회색 원(캐릭터 자리) + 헤드라인 2줄로 줄바꿈 | J6: cmp_03.png | K6: S3-06 · S3-08 · FIG-05 | L6: 개발 (원형 캐릭터는 FIG-05 결정 후) | M6: S-03
A7: BUG-06 | B7: 증서 테두리 장식 없음 | C7: Minor | D7: P2 | E7: 개발 수정 | F7: SC-RP-07 A · B · C | G7: https://dev-meli-web.meli.health/report-3gi?state=nice 마지막 화면 | H7: 금박 테두리 + 이중 내부 라인 + 마름모 6개 (S7-04) | I7: 금박 테두리만 · 내부 라인 · 마름모 없음 | J7: cmp_07A.png | K7: S7-04 | L7: 개발 | M7: C-01 · C-04
A8: BUG-07 | B8: 비대상 화면 아이콘 · 버튼 배치가 목업과 다름 | C8: Minor | D8: P2 | E8: 확인 필요 | F8: SYS-05 (P20) | G8: https://dev-meli-web.meli.health/report-3gi?state=sys05 | H8: 본문 위 원형 아이콘 · [홈으로 돌아가기]는 하단 전체 폭 흰 버튼 (목업 1136:5858) | I8: 아이콘 없음 · 버튼이 본문 바로 아래 좁은 회색 버튼 | J8: cmp_sys05.png | K8: P20 · FIG-08 | L8: 기획(아이콘 확정) → 개발 | M8: E-08
A9: BUG-08 | B9: 스크롤 힌트가 카드 하단을 가림 | C9: Minor | D9: P2 | E9: 앱 확인 | F9: SC-RP-04B · 05 · 06 | G9: https://dev-meli-web.meli.health/report-3gi?state=nice 04B · 05 화면 진입 직후 | H9: 진입 직후만 하단 고정 · 본문을 가리지 않음 (S1-05 v3.2) | I9: 05 안내박스 마지막 줄 · 04B 하단 문구 위에 힌트가 겹침 (375×812) | J9: cmp_05.png | K9: S1-05 · FE-05 | L9: 개발 | M9: S-08
A10: BUG-09 | B10: TOP 3 게임명 줄바꿈 · 게이지 라벨 위치 | C10: Trivial | D10: P3 | E10: 확인 필요 | F10: SC-RP-04 · 05 | G10: https://dev-meli-web.meli.health/report-3gi?state=nice 04 · 05 화면 | H10: "재밌는 숫자 퍼즐 9X9" 한 줄 / 게이지 "양호" "위험" 라벨이 아크 옆 (목업) | I10: 게임명 2줄 / 라벨이 아크 끝 아래 | J10: cmp_04.png | K10: S4-06 · S5-04 | L10: 개발 | M10: S-04 · S-06
A12: 새 결함은 아래 빈 행에 BUG-06부터 이어서 적습니다. 심각도: Blocker 사용 불가 · Major 잘못된 정보 · Minor 정본과 다름 · Trivial 표기

Sheet 피그마 정리
A1: ID | B1: 화면 | C1: 목업 | D1: 디스크립션 | E1: 개발은 어느 쪽 | F1: 제안 | G1: 피그마 노드 | H1: 처리 결과
A2: FIG-01 | B2: SC-RP-08 완료 본문 | C2: 2줄 · {전화번호} | D2: 4줄 · 032-453-6160 (v3.2) | E2: 목업(2줄) | F2: 목업 카드를 4줄 · 6160으로 수정 (Pretendard 폰트라 피그마에서 직접) | G2: 1463:1286
A3: FIG-02 | B3: SC-RP-08 배치 | C3: 배지 → 프로그램명 → 카드(✓ · 제목 · 본문) | D3: S8-02 "배지 바로 아래 큰 제목" | E3: 목업 | F3: 목업 유지 · 디스크립션 S8-02 문구만 "카드 안 큰 제목"으로 정정 (권장) | G3: 1484:1453
A4: FIG-03 | B4: 08-a 실패 제목 · 프로그램명 | C4: "신청이 완료되지 못했습니다" · 프로그램명 없음 | D4: "신청하지 못했습니다." · S8-04 프로그램명 완료·실패 공통 | E4: 확인 불가 (샘플 없음) | F4: 제목 하나로 확정 · 실패 화면 프로그램명 유무 확정 | G4: 1461:6901
A5: FIG-04 | B5: SC-RP-01 배지 | C5: "2026 인천 남동구 보건소 치매 예방 3기" | D5: S1-01 "2026년 인천 남동구 보건소 치매 예방 3기" | E5: 목업 | F5: "2026" / "2026년" 중 하나로 확정 | G5: 1239:1351
A6: FIG-05 | B6: SC-RP-03 개인화 멘트 | C6: 원형 캐릭터 없음 · 헤드라인 1줄 | D6: S3-08 "좌측 46px 원형 캐릭터 + 우측 2줄" | E6: 디스크립션(회색 원) | F6: 캐릭터를 넣을지 확정 — 넣으면 에셋 필요 | G6: 1240:1351
A7: FIG-06 | B7: SC-RP-05 게이지 각도 | C7: 반원에 가까운 아크 | D7: S5-04 "145° → 20° (125°)" · S5-05 "145 − 점수 × 8.333" (v2 값) | E7: 180° 반원 | F7: 디스크립션을 정본 v3.0 "180° · 180 − 점수 × 12"로 정정 | G7: 1239:1965
A8: FIG-07 | B8: SC-RP-07 인장 | C8: 둥근 사각 · 기울어짐 | D8: S7-13 "48×48 원형 인장" | E8: 목업 | F8: 목업 유지 · 디스크립션을 "둥근 사각"으로 정정 (권장) | G8: 1264:1433
A9: FIG-08 | B9: SYS-05 아이콘 | C9: 회색 원(아이콘 자리) | D9: P20 "제목 없이 본문 + 버튼" (아이콘 언급 없음) | E9: 아이콘 없음 | F9: 아이콘을 넣을지 확정 — 넣으면 에셋 필요 | G9: 1136:5858
A10: FIG-09 | B10: SC-RP-02 참여율 샘플값 | C10: 142일인데 69% | D10: F-02: 142 ÷ 242 = 59% | E10: 59% | F10: 목업 샘플값을 59%로 정정 (표기 오류 · 개발 영향 없음) | G10: 1122:856
A12: 피그마 안에서 목업과 디스크립션이 서로 다른 곳입니다. QA 기준이 피그마라서, 하나로 맞춘 뒤 개발에 알려야 합니다.

Sheet 결정 필요
A1: ID | B1: 내용 | C1: 지금 상태 | D1: 선택지 | E1: 기한 | F1: 결정 내용 | G1: 결정일 | H1: 근거
A2: Q-1 | B2: 4기 명칭이 화면마다 다름 | C2: 리포트 완료 "2027년 인천 남동구 보건소 치매예방 프로그램 4기" · 리포트 시트 "…프로그램을"(4기 없음) · 신청폼 첫 화면 "치매예방교실 4기" · 입력 폼 "두뇌운동 치매예방교실 4기" · 케어센터 "두뇌운동 치매예방교실-27년" | D2: 대외 명칭 1개 확정 · 리포트 시트에 "4기" 추가(권장) | E2: 10/15 | H2: K-13 · 개발 §A ①
A3: Q-2 | B3: 기관명 두 가지 | C3: 신청폼 첫 화면 "인천 남동구 보건소" · 입력 폼 배지 "인천 남동구 치매안심센터" · 증서 "인천남동구 보건소" | D3: 보건소 / 치매안심센터 중 하나, 띄어쓰기 포함 | E3: 10/15 | H3: K-09 · 개발 §A ①
A4: Q-3 | B4: 신청폼 4기 즉시 승인 | C4: 입력 폼 "신청하면 바로 참여가 확정되고, 앱 설치 안내 문자가 갑니다" · 신청폼 기획 v1.0(9/21)은 관리자 승인 | D4: 즉시 승인 유지 / 승인 대기 · 4기 접수 시작일과 문자 문구 | E4: 10/15 | H4: 개발 D-2 · form 06 #1
A5: Q-4 | B5: 리포트 신청과 신청폼 신청 중복 | C5: 기획상 두 경로 연결 없음 (리포트 = 의사만 저장 · 문자 없음) | D5: 중복 1건 처리 방식 · 리포트 신청자에게 4기 시작 문자 여부 · 명단 이관 A/B | E5: 10/15 | H5: 개발 §A ④
A6: Q-5 | B6: 60세 이상 조건 검증 | C6: 첫 화면에만 "60세 이상" 표기 · 입력 폼 검증 미확인 | D6: 생년월일로 막음 / 받고 보건소가 거름 | E6: 10/15 | H6: —
A7: Q-6 | B7: 3기 신청폼 링크 | C7: namdong3 열림 · 제출 시 3기로 접수 | D7: 4기로 보냄 / 모집 종료 화면 / 그대로 | E7: 10/15 | H7: 개발 §A ⑤
A8: Q-7 | B8: 11/1 하루 안내 공백 | C8: 10/31 종료 ~ 11/2 공개 사이 카드 · 안내 없음 | D8: 그대로 / 11/1로 당김 | E8: 10/15 | H8: 개발 §A ②
A9: Q-8 | B9: 푸시 · 사전 안내 문구 | C9: 미발송 기본값 | D9: 보냄(문구) / 안 보냄 | E9: 10/15 (마지막 기한) | H9: IA-Q-04 · IA-Q-05 · 개발 §A ⑥

Sheet 데이터 요청
A1: # | B1: 요청 (개발) | C1: 왜 | D1: 관련 TC | E1: 요청일 | F1: 받은 날 | G1: 파일 · 링크
A2: 1 | B2: 등급별 인원 A / B / C (F-16 변경 전 · 후) | C2: 12명 B → A가 맞는지 | D2: S-02 | E2: 2026-10-12
A3: 2 | B3: B → A로 바뀐 12명 목록 (참여일 · 게임 횟수 · 판정 조건) | C3: 두 번째 조건 단독 발동 확인 | D3: S-02 | E3: 2026-10-12
A4: 3 | B4: 판정 근거 로그 샘플 (조건 1 / 조건 2 / 둘 다) | C4: K-06 · D-30 | D4: S-02 | E4: 2026-10-12
A5: 4 | B5: 폼 동의 기록 없는 계정 목록 (55명) · 그중 리포트 대상 수 | C5: 07-m 범위 | D5: A-09 | E5: 2026-10-12
A6: 5 | B6: 테스트 계정 ①~④ 리포트 원값 (payload) | C6: 화면 숫자와 대조 | D6: S-02 | E6: 2026-10-12
A7: 6 | B7: 4기 신청 의사 저장 테이블 구조 + dev 기록 (누가 · 언제) | C7: 명단 이관 (§A ④) | D7: A-03 · A-06 | E7: 2026-10-12
A8: 7 | B8: 측정 이벤트 집계 (섹션별 방문 수 · 방문자 수 · 평균 체류) | C8: IA-Q-06 | D8: M-01 · M-02 | E8: 2026-10-12
A9: 8 | B9: 실패 화면 샘플 주소 (state=08a) · 측정 1회 / 0회 · 걸음 미연동 계정 | C9: 웹 샘플로 못 본 화면 | D9: A-07 · S-06 · S-07 | E9: 2026-10-12

Sheet 계정 · 안내
A1: 테스트 계정 (개발 서버 전용 가상 번호 · 인증번호는 개발이 전달)
A2: 표기 | B2: 번호 | C2: 이름 | D2: 등급 | E2: 주로 볼 것
A3: ① | B3: 099-0002-8800 | C3: 박용주 | D3: A 수료 | E3: 첫 진입 · 자동 팝업 · 저장 · 4기 신청 전체
A4: ② | B4: 099-0002-1234 | C4: 박희로 | D4: A · 4기 신청 완료 | E4: 꽉 찬 데이터(게임 71회 · 마음 12일 · 1위) · 07-l
A5: ③ | B5: 099-3333-3333 | C5: 서비스 | D5: B 참여기록 | E5: 참여기록 라벨 · 파일명
A6: ④ | B6: 099-5555-5555 | C6: 김철순 | D6: C 참여확인 | E6: 저장 버튼 없음
A7: ⑤ | B7: 099-0002-4096 | C7: 김철순 | D7: A · 동의 기록 없음 | E7: 다른 프로그램 진행 중 → 카드 없음 · 07-m 4기 버튼 숨김
A8: ⑥ | B8: 099-0988-8888 | C8: 안녕하세요 | D8: 공개 전 | E8: 카드 없음 · 링크로 열면 "아직 볼 수 없어요"
A9: ⑦ | B9: 099-0008-9999 | C9: 원메딕스 | D9: 리포트 없음 | E9: 카드 없음 · 링크로 열면 P20 비대상 안내
A11: 우선순위
A12: P1 | B12: 배포 차단 | C12: 실패하면 배포하지 않습니다. 진입 · 저장 · 4기 신청 · 닫기 · 번호 · 비대상처럼 사용자가 막히거나 잘못된 정보를 받는 항목
A13: P2 | B13: 화면 · 문구 | C13: 정본과 문구 · 숫자 · 배치가 같은지. 실패해도 배포는 가능하지만 출시 전 수정 대상
A14: P3 | B14: 예외 · 환경 | C14: 권한 거부 · 오프라인 · 작은 화면 · 큰 글씨 등 드문 상황. 출시 후 수정 가능
A16: 결과 값
A17: 통과 | B17: 기대 결과와 같음
A18: 실패 | B18: 다름 → 결함 시트에 BUG 번호로 적고 TC의 결함 ID 칸에 연결
A19: 보류 | B19: 판단에 결정 · 데이터가 더 필요
A20: 미실행 | B20: 아직 안 함
A21: 해당없음 | B21: 이 환경에서는 볼 수 없음
A23: 웹 샘플 주소 (가짜 데이터 · 눌러도 저장 안 됨)
A24: 수료 A | B24: https://dev-meli-web.meli.health/report-3gi?state=nice
A25: 참여기록 B | B25: https://dev-meli-web.meli.health/report-3gi?state=07B
A26: 참여확인 C | B26: https://dev-meli-web.meli.health/report-3gi?state=07C
A27: 4기 신청 완료 | B27: https://dev-meli-web.meli.health/report-3gi?state=07l
A28: 비대상 P20 | B28: https://dev-meli-web.meli.health/report-3gi?state=sys05
A29: 신청폼 4기 (제출하면 실제 문자 — 본인 번호만) | B29: https://dev-meli-web.meli.health/invitations/namdong4

Sheet 스크린샷
A1: 개발 dev(375×812, 빨강) vs 피그마 목업(초록) — 2026-10-12
A3: SC-RP-01 표지 · BUG-03 | H3: SC-RP-02 · BUG-04
A4: cmp_01.png | H4: cmp_02.png
A33: SC-RP-03 · BUG-05 | H33: SC-RP-04 · BUG-09
A34: cmp_03.png | H34: cmp_04.png
A63: SC-RP-04B | H63: SC-RP-05 · BUG-08 · 09
A64: cmp_04B.png | H64: cmp_05.png
A93: SC-RP-06 | H93: SC-RP-07 A · BUG-06
A94: cmp_06.png | H94: cmp_07A.png
A123: SC-RP-07 B | H123: SC-RP-07 C
A124: cmp_07B.png | H124: cmp_07C.png
A153: 07-h 시트 | H153: 07-l
A154: cmp_07h.png | H154: cmp_07l.png
... A214: dev_form4_landing.png | H214: dev_form3_landing.png
